<?xml version="1.0"?>
<robot name="surveillance_robot">

  <!-- BASE -->
  <link name="base_link">
    <visual>
      <geometry>
        <box size="0.4 0.3 0.1"/>
      </geometry>
      <material name="blue">
        <color rgba="0 0 1 1"/>
      </material>
    </visual>
  </link>

  <!-- LEFT WHEEL -->
  <link name="left_wheel">
    <visual>
      <geometry>
        <cylinder radius="0.05" length="0.02"/>
      </geometry>
      <origin rpy="1.57 0 0"/>
    </visual>
  </link>

  <joint name="left_wheel_joint" type="continuous">
    <parent link="base_link"/>
    <child link="left_wheel"/>
    <origin xyz="0 0.15 -0.05"/>
    <axis xyz="0 1 0"/>
  </joint>

  <!-- RIGHT WHEEL -->
  <link name="right_wheel">
    <visual>
      <geometry>
        <cylinder radius="0.05" length="0.02"/>
      </geometry>
      <origin rpy="1.57 0 0"/>
    </visual>
  </link>

  <joint name="right_wheel_joint" type="continuous">
    <parent link="base_link"/>
    <child link="right_wheel"/>
    <origin xyz="0 -0.15 -0.05"/>
    <axis xyz="0 1 0"/>
  </joint>

  <!-- CAMERA -->
  <link name="camera_link">
    <visual>
      <geometry>
        <box size="0.05 0.05 0.05"/>
      </geometry>
    </visual>
  </link>

  <joint name="camera_joint" type="fixed">
    <parent link="base_link"/>
    <child link="camera_link"/>
    <origin xyz="0 0 0.1"/>
  </joint>


  <!-- ================= GAZEBO PLUGINS ================= -->

  <!-- DIFFERENTIAL DRIVE -->
  <gazebo>
    <plugin name="diff_drive" filename="libgazebo_ros_diff_drive.so">
      <left_joint>left_wheel_joint</left_joint>
      <right_joint>right_wheel_joint</right_joint>

      <wheel_separation>0.3</wheel_separation>
      <wheel_diameter>0.1</wheel_diameter>

      <command_topic>cmd_vel</command_topic>
      <odometry_topic>odom</odometry_topic>
    </plugin>
  </gazebo>


  <!-- CAMERA -->
  <gazebo reference="camera_link">
    <sensor type="camera" name="camera">
      <update_rate>30</update_rate>

      <camera>
        <horizontal_fov>1.047</horizontal_fov>
        <image>
          <width>640</width>
          <height>480</height>
        </image>
      </camera>

      <plugin name="camera_plugin" filename="libgazebo_ros_camera.so">
        <camera_name>camera</camera_name>
        <image_topic_name>image_raw</image_topic_name>
      </plugin>
    </sensor>
  </gazebo>

</robot>
